<?xml version='1.0'?>

<!--roslaunch urdf_tutorial display.launch model:='$(find revvyframework_ros)/urdf/jetson.xacro'-->
<robot name="revvy_jetson" xmlns:xacro="http://www.ros.org/wiki/xacro">
  <!--gazebo plugins-->
  <!--xacro:include filename="$(find revvyframework_ros)/urdf/jetson.gazebo" /-->

  <link name="base_footprint"></link>

  <!--base_link-->
  <link name='base_link'>
    <pose>0 0 0.1 0 0 0</pose>

    <inertial>
      <mass value="1.0"/>
      <origin xyz="0.0 0 0.09" rpy=" 0 0 0"/>
      <inertia
          ixx="0.1" ixy="0" ixz="0"
          iyy="0.1" iyz="0"
          izz="0.1"
      />
    </inertial>

    <collision name='collision'>
      <origin xyz="0 0 0.09" rpy=" 0 0 0"/> 
      <geometry>
        <box size=".20 .08 .15"/>
      </geometry>
    </collision>

    <visual name='base_link_visual'>
      <origin xyz="0 0 0.09" rpy=" 0 0 0"/>
      <geometry>
        <!--box size=".20 .08 .15"/-->
        <mesh filename = "package://revvyframework_ros/meshes/revvy_jetbot.dae"/>
      </geometry>
    </visual>

  </link>

  <joint name="base_footprint_joint" type="fixed">
    <origin xyz="0 0 0" rpy="0 0 0" />
    <parent link="base_footprint"/>
    <child link="base_link" />
  </joint>

  <!--IMU-->
  <link name="imu_link">
  </link>

  <joint name="imu_joint" type="fixed">
    <origin xyz="0 0 0.08" rpy="0 0 0" />
    <parent link="base_link"/>
    <child link="imu_link" />
  </joint>

  <!--front left wheel-->
  <link name='front_left_wheel'>
    <inertial>
      <mass value="0.2"/>
      <origin xyz="0.0 0 0" rpy=" 0 1.5708 1.5708"/>
      <inertia
          ixx="0.1" ixy="0" ixz="0"
          iyy="0.1" iyz="0"
          izz="0.1"
      />
    </inertial>

    <collision name='collision'>
      <origin xyz="0.0 0 0" rpy=" 0 1.5708 1.5708"/> 
      <geometry>
        <cylinder radius = ".035" length = ".03"/>
      </geometry>
    </collision>

    <visual name='front_left_wheel_visual'>
      <origin xyz="0.0 0 0" rpy=" 0 1.5708 1.5708"/>
      <geometry>
        <!--cylinder radius = ".035" length = ".03"/-->
        <mesh filename = "package://revvyframework_ros/meshes/wheel.dae" scale="1.08 1.08 1.08"/>
      </geometry>
    </visual>
  </link>

  <joint type="continuous" name="front_left_wheel_hinge">
    <origin xyz="0.065 0.055 0.035" rpy="0 0 0"/>
    <parent link="base_link"/>
    <child link="front_left_wheel"/>
    <axis xyz="0 1 0" rpy="0 0 0"/>
    <limit effort="10000" velocity="1000"/>
    <dynamics damping="0.0" friction="0.0"/>
  </joint>

  <!--rear left wheel-->
  <link name='rear_left_wheel'>
    <inertial>
      <mass value="0.2"/>
      <origin xyz="0.0 0 0" rpy=" 0 1.5708 1.5708"/>
      <inertia
          ixx="0.1" ixy="0" ixz="0"
          iyy="0.1" iyz="0"
          izz="0.1"
      />
    </inertial>

    <collision name='collision'>
      <origin xyz="0.0 0 0" rpy=" 0 1.5708 1.5708"/> 
      <geometry>
        <cylinder radius = ".035" length = ".03"/>
      </geometry>
    </collision>

    <visual name='rear_left_wheel_visual'>
      <origin xyz="0.0 0 0" rpy=" 0 1.5708 1.5708"/>
      <geometry>
        <!--cylinder radius = ".035" length = ".03"/-->
        <mesh filename = "package://revvyframework_ros/meshes/wheel.dae" scale="1.08 1.08 1.08"/>
      </geometry>
    </visual>
  </link>

  <joint type="continuous" name="rear_left_wheel_hinge">
    <origin xyz="-0.065 0.055 0.035" rpy="0 0 0"/>
    <parent link="base_link"/>
    <child link="rear_left_wheel"/>
    <axis xyz="0 1 0" rpy="0 0 0"/>
    <limit effort="10000" velocity="1000"/>
    <dynamics damping="0.0" friction="0.0"/>
  </joint>

  <!--front right wheel-->
  <link name='front_right_wheel'>
    <inertial>
      <mass value="0.2"/>
      <origin xyz="0.0 0 0" rpy=" 0 1.5708 1.5708"/>
      <inertia
          ixx="0.1" ixy="0" ixz="0"
          iyy="0.1" iyz="0"
          izz="0.1"
      />
    </inertial>

    <collision name='collision'>
      <origin xyz="0.0 0 0" rpy=" 0 1.5708 1.5708"/> 
      <geometry>
        <cylinder radius = ".035" length = ".03"/>
      </geometry>
    </collision>

    <visual name='front_right_wheel_visual'>
      <origin xyz="0.0 0 0" rpy=" 0 1.5708 -1.5708"/>
      <geometry>
        <!--cylinder radius = ".035" length = ".03"/-->
        <mesh filename = "package://revvyframework_ros/meshes/wheel.dae" scale="1.08 1.08 1.08"/>
      </geometry>
    </visual>
  </link>

  <joint type="continuous" name="front_right_wheel_hinge">
    <origin xyz="0.065 -0.055 0.035" rpy="0 0 0"/>
    <parent link="base_link"/>
    <child link="front_right_wheel"/>
    <axis xyz="0 1 0" rpy="0 0 0"/>
    <limit effort="10000" velocity="1000"/>
    <dynamics damping="0.0" friction="0.0"/>
  </joint>

  <!--rear right wheel-->
  <link name='rear_right_wheel'>
    <inertial>
      <mass value="0.2"/>
      <origin xyz="0.0 0 0" rpy=" 0 1.5708 1.5708"/>
      <inertia
          ixx="0.1" ixy="0" ixz="0"
          iyy="0.1" iyz="0"
          izz="0.1"
      />
    </inertial>

    <collision name='collision'>
      <origin xyz="0.0 0 0" rpy=" 0 1.5708 1.5708"/> 
      <geometry>
        <cylinder radius = ".035" length = ".03"/>
      </geometry>
    </collision>

    <visual name='rear_right_wheel_visual'>
      <origin xyz="0.0 0 0" rpy=" 0 1.5708 -1.5708"/>
      <geometry>
        <!--cylinder radius = ".035" length = ".03"/-->
        <mesh filename = "package://revvyframework_ros/meshes/wheel.dae" scale="1.08 1.08 1.08"/>
      </geometry>
    </visual>
  </link>

  <joint type="continuous" name="rear_right_wheel_hinge">
    <origin xyz="-0.065 -0.055 0.035" rpy="0 0 0"/>
    <parent link="base_link"/>
    <child link="rear_right_wheel"/>
    <axis xyz="0 1 0" rpy="0 0 0"/>
    <limit effort="10000" velocity="1000"/>
    <dynamics damping="0.0" friction="0.0"/>
  </joint>

  <!--RGBD camera-->
  <link name='rgbd_camera_link'>
    <pose>0 0 0 0 0 0</pose>
    <inertial>
      <mass value="0.1"/>
      <origin xyz="0 0 0" rpy=" 0 0 0"/>
      <inertia
          ixx="1e-6" ixy="0" ixz="0"
          iyy="1e-6" iyz="0"
          izz="1e-6"
      />
    </inertial>

    <collision name='collision'>
      <origin xyz="0 0 0" rpy=" 0 0 0"/> 
      <geometry>
        <box size=".05 .05 .05"/>
      </geometry>
    </collision>

    <visual name='rgbd_camera_link_visual'>
      <origin xyz="0 0 0" rpy=" 0 0 0"/>
      <geometry>
        <!--box size=".05 .05 .05"/-->
        <mesh filename = "package://revvyframework_ros/meshes/d435.dae"/>
      </geometry>
    </visual>

  </link>

  <joint type="fixed" name="rgbd_camera_joint">
    <origin xyz="0.08 0 0.15" rpy="0 0 0"/>
    <child link="rgbd_camera_link"/>
    <parent link="base_link"/>
    <axis xyz="0 1 0" rpy="0 0 0"/>
  </joint>

  <link name="rgbd_camera_depth_frame">
  </link>

  <joint type="fixed" name="rgbd_camera_depth_joint">
    <origin xyz="0 0 0" rpy="0 0 0"/>
    <child link="rgbd_camera_depth_frame"/>
    <parent link="rgbd_camera_link"/>
  </joint>

  <link name="rgbd_camera_depth_optical_frame">
  </link>

  <joint type="fixed" name="rgbd_camera_depth_optical_joint">
    <origin xyz="0 0 0" rpy="-1.5707 0 -1.5707"/>
    <child link="rgbd_camera_depth_optical_frame"/>
    <parent link="rgbd_camera_depth_frame"/>
  </joint>

  <link name="rgbd_camera_color_frame">
  </link>

  <joint type="fixed" name="rgbd_camera_color_joint">
    <origin xyz="0 0 0" rpy="0 0 0"/>
    <child link="rgbd_camera_color_frame"/>
    <parent link="rgbd_camera_link"/>
  </joint>

  <link name="rgbd_camera_color_optical_frame">
  </link>

  <joint type="fixed" name="rgbd_camera_color_optical_joint">
    <origin xyz="0 0 0" rpy="-1.5707 0 -1.5707"/>
    <child link="rgbd_camera_color_optical_frame"/>
    <parent link="rgbd_camera_color_frame"/>
  </joint>
  

  <!--camera-->
  <link name='main_camera_link'>
    <pose>0 0 0 0 0 0</pose>
    <inertial>
      <mass value="0.1"/>
      <origin xyz="0 0 0" rpy=" 0 0 0"/>
      <inertia
          ixx="1e-6" ixy="0" ixz="0"
          iyy="1e-6" iyz="0"
          izz="1e-6"
      />
    </inertial>

    <collision name='collision'>
      <origin xyz="0 0 0" rpy=" 0 0 0"/> 
      <geometry>
        <box size=".05 .05 .05"/>
      </geometry>
    </collision>

    <visual name='main_camera_link_visual'>
      <origin xyz="0 0 0" rpy=" 0 0 0"/>
      <geometry>
        <!--box size=".05 .05 .05"/-->
        <mesh filename = "package://revvyframework_ros/meshes/picam.dae" scale="0.001 0.001 0.001"/>
      </geometry>
    </visual>

  </link>

  <joint type="fixed" name="main_camera_joint">
    <origin xyz="0.08 0 0.115" rpy="-1.5707 0 -1.5707"/>
    <child link="main_camera_link"/>
    <parent link="base_link"/>
    <axis xyz="0 1 0" rpy="0 0 0"/>
  </joint>

    <!--lidar-->
  <link name='scan'>
    <inertial>
      <mass value="1e-5"/>
      <origin xyz="0 0 0" rpy=" 0 0 0"/>
      <inertia
          ixx="1e-6" ixy="0" ixz="0"
          iyy="1e-6" iyz="0"
          izz="1e-6"
      />
    </inertial>

    <collision name='collision'>
      <origin xyz="0 0 0" rpy=" 0 0 0"/> 
      <geometry>
        <box size=".1 .1 .1"/>
      </geometry>
    </collision>

    <visual name='scan_visual'>
      <origin xyz="0 0 0" rpy=" 0 0 3.1415"/>
      <geometry>
        <mesh filename = "package://revvyframework_ros/meshes/rplidar.dae"/>
      </geometry>
    </visual>

  </link>

  <joint type="fixed" name="scan_joint">
    <origin xyz="-0.066 0 0.23" rpy="0 0 0"/>
    <child link="scan"/>
    <parent link="base_link"/>
    <axis xyz="0 1 0" rpy="0 0 0"/>
  </joint>

</robot>



